<?xml version="1.0" encoding="UTF-8"?>
<!-- Generated by org.testng.reporters.JUnitXMLReporter -->
<testsuite ignored="0" hostname="DESKTOP-U9882TR" failures="1" tests="2" name="EdgeTest" time="39.848" errors="0" timestamp="2024-07-03T20:02:51 EEST">
  <testcase classname="tests.ContactFormTest" name="sendValidMessage" time="14.174"/>
  <testcase classname="tests.ContactFormTest" name="sendInvalidMessage" time="11.009">
    <failure type="java.lang.AssertionError" message="expected [Thank you for your message. It has been sent.] but found [One or more fields have an error. Please check and try again.]">
      <![CDATA[java.lang.AssertionError: expected [Thank you for your message. It has been sent.] but found [One or more fields have an error. Please check and try again.]
at tests.ContactFormTest.sendInvalidMessage(ContactFormTest.java:49)
at java.base/java.util.ArrayList.forEach(ArrayList.java:1511)
at java.base/java.util.concurrent.FutureTask.run(FutureTask.java:264)
at java.base/java.util.concurrent.ThreadPoolExecutor.runWorker(ThreadPoolExecutor.java:1136)
at java.base/java.util.concurrent.ThreadPoolExecutor$Worker.run(ThreadPoolExecutor.java:635)
at java.base/java.lang.Thread.run(Thread.java:840)
... Removed 24 stack frames]]>
    </failure>
  </testcase> <!-- sendInvalidMessage -->
</testsuite> <!-- EdgeTest -->
