<?xml version="1.0" encoding="UTF-8"?>
<!-- Generated by org.testng.reporters.JUnitXMLReporter -->
<testsuite ignored="0" hostname="DESKTOP-U9882TR" failures="1" tests="2" name="test" time="30.912" errors="0" timestamp="2024-07-03T20:26:31 EEST">
  <testcase classname="tests.ContactFormTest" name="sendValidMessage" time="11.86"/>
  <testcase classname="tests.ContactFormTest" name="sendInvalidMessage" time="9.186">
    <failure type="java.lang.AssertionError" message="expected [Thank you for your message. It has been sent.] but found [One or more fields have an error. Please check and try again.]">
      <![CDATA[java.lang.AssertionError: expected [Thank you for your message. It has been sent.] but found [One or more fields have an error. Please check and try again.]
at tests.ContactFormTest.sendInvalidMessage(ContactFormTest.java:49)
at java.base/java.util.ArrayList.forEach(ArrayList.java:1511)
... Removed 33 stack frames]]>
    </failure>
  </testcase> <!-- sendInvalidMessage -->
</testsuite> <!-- test -->
